12-02-2022 17:14:19 - WARNING - Database not found! Creating fresh ... [database_handler/_get_connection]
12-02-2022 17:14:19 - INFO - Database successfully created! [database_handler/_create_database]
12-02-2022 17:14:19 - INFO - Connection to database established. [database_handler/create_instance]
12-02-2022 17:14:19 - WARNING - PyNaCl is not installed, voice will NOT be supported [discord.client/__init__]
12-02-2022 17:14:19 - INFO - Loaded extensions: [root/<module>]
12-02-2022 17:14:19 - ERROR - ExtensionFailed: Extension 'cogs.licenses' raised an error: ModuleNotFoundError: No module named 'dateutil' Failed to load extension cogs.licenses [root/<module>]
12-02-2022 17:14:19 - WARNING - ['Traceback (most recent call last):\n', '  File "C:\\Users\\giwrg\\AppData\\Local\\Programs\\Python\\Python39\\lib\\site-packages\\discord\\ext\\commands\\bot.py", line 606, in _load_from_module_spec\n    spec.loader.exec_module(lib)\n', '  File "<frozen importlib._bootstrap_external>", line 850, in exec_module\n', '  File "<frozen importlib._bootstrap>", line 228, in _call_with_frames_removed\n', '  File "C:\\Users\\giwrg\\OneDrive\\Υπολογιστής\\Licensy-0.9.14\\cogs\\licenses.py", line 3, in <module>\n    from dateutil import parser\n', "ModuleNotFoundError: No module named 'dateutil'\n", '\nThe above exception was the direct cause of the following exception:\n\n', 'Traceback (most recent call last):\n', '  File "C:\\Users\\giwrg\\OneDrive\\Υπολογιστής\\Licensy-0.9.14\\bot.py", line 111, in <module>\n    bot.load_extension(cog_path)\n', '  File "C:\\Users\\giwrg\\AppData\\Local\\Programs\\Python\\Python39\\lib\\site-packages\\discord\\ext\\commands\\bot.py", line 678, in load_extension\n    self._load_from_module_spec(spec, name)\n', '  File "C:\\Users\\giwrg\\AppData\\Local\\Programs\\Python\\Python39\\lib\\site-packages\\discord\\ext\\commands\\bot.py", line 609, in _load_from_module_spec\n    raise errors.ExtensionFailed(key, e) from e\n', "discord.ext.commands.errors.ExtensionFailed: Extension 'cogs.licenses' raised an error: ModuleNotFoundError: No module named 'dateutil'\n"] [root/<module>]
12-02-2022 17:14:19 - ERROR - ExtensionFailed: Extension 'cogs.bot_owner_commands' raised an error: ModuleNotFoundError: No module named 'dateutil' Failed to load extension cogs.bot_owner_commands [root/<module>]
12-02-2022 17:14:19 - WARNING - ['Traceback (most recent call last):\n', '  File "C:\\Users\\giwrg\\AppData\\Local\\Programs\\Python\\Python39\\lib\\site-packages\\discord\\ext\\commands\\bot.py", line 606, in _load_from_module_spec\n    spec.loader.exec_module(lib)\n', '  File "<frozen importlib._bootstrap_external>", line 850, in exec_module\n', '  File "<frozen importlib._bootstrap>", line 228, in _call_with_frames_removed\n', '  File "C:\\Users\\giwrg\\OneDrive\\Υπολογιστής\\Licensy-0.9.14\\cogs\\bot_owner_commands.py", line 8, in <module>\n    from helpers.converters import license_duration\n', '  File "C:\\Users\\giwrg\\OneDrive\\Υπολογιστής\\Licensy-0.9.14\\helpers\\converters.py", line 3, in <module>\n    from dateutil.relativedelta import relativedelta\n', "ModuleNotFoundError: No module named 'dateutil'\n", '\nThe above exception was the direct cause of the following exception:\n\n', 'Traceback (most recent call last):\n', '  File "C:\\Users\\giwrg\\OneDrive\\Υπολογιστής\\Licensy-0.9.14\\bot.py", line 111, in <module>\n    bot.load_extension(cog_path)\n', '  File "C:\\Users\\giwrg\\AppData\\Local\\Programs\\Python\\Python39\\lib\\site-packages\\discord\\ext\\commands\\bot.py", line 678, in load_extension\n    self._load_from_module_spec(spec, name)\n', '  File "C:\\Users\\giwrg\\AppData\\Local\\Programs\\Python\\Python39\\lib\\site-packages\\discord\\ext\\commands\\bot.py", line 609, in _load_from_module_spec\n    raise errors.ExtensionFailed(key, e) from e\n', "discord.ext.commands.errors.ExtensionFailed: Extension 'cogs.bot_owner_commands' raised an error: ModuleNotFoundError: No module named 'dateutil'\n"] [root/<module>]
12-02-2022 17:14:19 - ERROR - ExtensionFailed: Extension 'cogs.guild' raised an error: ModuleNotFoundError: No module named 'dateutil' Failed to load extension cogs.guild [root/<module>]
12-02-2022 17:14:19 - WARNING - ['Traceback (most recent call last):\n', '  File "C:\\Users\\giwrg\\AppData\\Local\\Programs\\Python\\Python39\\lib\\site-packages\\discord\\ext\\commands\\bot.py", line 606, in _load_from_module_spec\n    spec.loader.exec_module(lib)\n', '  File "<frozen importlib._bootstrap_external>", line 850, in exec_module\n', '  File "<frozen importlib._bootstrap>", line 228, in _call_with_frames_removed\n', '  File "C:\\Users\\giwrg\\OneDrive\\Υπολογιστής\\Licensy-0.9.14\\cogs\\guild.py", line 6, in <module>\n    from helpers.converters import license_duration\n', '  File "C:\\Users\\giwrg\\OneDrive\\Υπολογιστής\\Licensy-0.9.14\\helpers\\converters.py", line 3, in <module>\n    from dateutil.relativedelta import relativedelta\n', "ModuleNotFoundError: No module named 'dateutil'\n", '\nThe above exception was the direct cause of the following exception:\n\n', 'Traceback (most recent call last):\n', '  File "C:\\Users\\giwrg\\OneDrive\\Υπολογιστής\\Licensy-0.9.14\\bot.py", line 111, in <module>\n    bot.load_extension(cog_path)\n', '  File "C:\\Users\\giwrg\\AppData\\Local\\Programs\\Python\\Python39\\lib\\site-packages\\discord\\ext\\commands\\bot.py", line 678, in load_extension\n    self._load_from_module_spec(spec, name)\n', '  File "C:\\Users\\giwrg\\AppData\\Local\\Programs\\Python\\Python39\\lib\\site-packages\\discord\\ext\\commands\\bot.py", line 609, in _load_from_module_spec\n    raise errors.ExtensionFailed(key, e) from e\n', "discord.ext.commands.errors.ExtensionFailed: Extension 'cogs.guild' raised an error: ModuleNotFoundError: No module named 'dateutil'\n"] [root/<module>]
12-02-2022 17:14:19 - INFO - 	cogs.bot_information [root/<module>]
12-02-2022 17:14:19 - INFO - 	cogs.help [root/<module>]
12-02-2022 17:14:19 - ERROR - ExtensionFailed: Extension 'cogs.top_gg_api' raised an error: ModuleNotFoundError: No module named 'dbl' Failed to load extension cogs.top_gg_api [root/<module>]
12-02-2022 17:14:19 - WARNING - ['Traceback (most recent call last):\n', '  File "C:\\Users\\giwrg\\AppData\\Local\\Programs\\Python\\Python39\\lib\\site-packages\\discord\\ext\\commands\\bot.py", line 606, in _load_from_module_spec\n    spec.loader.exec_module(lib)\n', '  File "<frozen importlib._bootstrap_external>", line 850, in exec_module\n', '  File "<frozen importlib._bootstrap>", line 228, in _call_with_frames_removed\n', '  File "C:\\Users\\giwrg\\OneDrive\\Υπολογιστής\\Licensy-0.9.14\\cogs\\top_gg_api.py", line 2, in <module>\n    import dbl\n', "ModuleNotFoundError: No module named 'dbl'\n", '\nThe above exception was the direct cause of the following exception:\n\n', 'Traceback (most recent call last):\n', '  File "C:\\Users\\giwrg\\OneDrive\\Υπολογιστής\\Licensy-0.9.14\\bot.py", line 111, in <module>\n    bot.load_extension(cog_path)\n', '  File "C:\\Users\\giwrg\\AppData\\Local\\Programs\\Python\\Python39\\lib\\site-packages\\discord\\ext\\commands\\bot.py", line 678, in load_extension\n    self._load_from_module_spec(spec, name)\n', '  File "C:\\Users\\giwrg\\AppData\\Local\\Programs\\Python\\Python39\\lib\\site-packages\\discord\\ext\\commands\\bot.py", line 609, in _load_from_module_spec\n    raise errors.ExtensionFailed(key, e) from e\n', "discord.ext.commands.errors.ExtensionFailed: Extension 'cogs.top_gg_api' raised an error: ModuleNotFoundError: No module named 'dbl'\n"] [root/<module>]
12-02-2022 17:14:19 - INFO - 	cogs.cmd_errors [root/<module>]
12-02-2022 17:14:19 - INFO - Starting activity loop.. [cogs.bot_information/before_activity_loop]
12-02-2022 17:14:20 - INFO - Connection to Discord established [root/on_connect]
12-02-2022 17:14:22 - INFO - Activity loop started! [cogs.bot_information/before_activity_loop]
12-02-2022 17:14:22 - INFO - Logged in as: FiveM $nban Helper - 823233083305623572	DiscordPy version: 1.7.3 [root/on_ready]
12-02-2022 17:14:22 - INFO - Successfully logged in and booted...! [root/on_ready]
12-02-2022 17:15:21 - ERROR - Can't get guild Luxury Shop prefix. Error:'NoneType' object is not subscriptable. Using '!' as prefix. [root/prefix_callable]
12-02-2022 17:15:25 - ERROR - Can't get guild Luxury Shop prefix. Error:'NoneType' object is not subscriptable. Using '!' as prefix. [root/prefix_callable]
12-02-2022 17:15:30 - ERROR - Can't get guild Luxury Shop prefix. Error:'NoneType' object is not subscriptable. Using '!' as prefix. [root/prefix_callable]
12-02-2022 17:15:43 - ERROR - Can't get guild Luxury Shop prefix. Error:'NoneType' object is not subscriptable. Using '!' as prefix. [root/prefix_callable]
12-02-2022 17:16:03 - ERROR - Can't get guild Luxury Shop prefix. Error:'NoneType' object is not subscriptable. Using '!' as prefix. [root/prefix_callable]
12-02-2022 17:16:48 - ERROR - Can't get guild Luxury Shop prefix. Error:'NoneType' object is not subscriptable. Using '!' as prefix. [root/prefix_callable]
12-02-2022 17:17:03 - ERROR - Can't get guild Luxury Shop prefix. Error:'NoneType' object is not subscriptable. Using '!' as prefix. [root/prefix_callable]
12-02-2022 17:19:49 - INFO - Connection to database established. [database_handler/create_instance]
12-02-2022 17:19:49 - WARNING - PyNaCl is not installed, voice will NOT be supported [discord.client/__init__]
12-02-2022 17:19:49 - INFO - Loaded extensions: [root/<module>]
12-02-2022 17:19:49 - ERROR - ExtensionFailed: Extension 'cogs.licenses' raised an error: ModuleNotFoundError: No module named 'dateutil' Failed to load extension cogs.licenses [root/<module>]
12-02-2022 17:19:49 - WARNING - ['Traceback (most recent call last):\n', '  File "C:\\Users\\giwrg\\AppData\\Local\\Programs\\Python\\Python39\\lib\\site-packages\\discord\\ext\\commands\\bot.py", line 606, in _load_from_module_spec\n    spec.loader.exec_module(lib)\n', '  File "<frozen importlib._bootstrap_external>", line 850, in exec_module\n', '  File "<frozen importlib._bootstrap>", line 228, in _call_with_frames_removed\n', '  File "C:\\Users\\giwrg\\OneDrive\\Υπολογιστής\\Licensy-0.9.14\\cogs\\licenses.py", line 3, in <module>\n    from dateutil import parser\n', "ModuleNotFoundError: No module named 'dateutil'\n", '\nThe above exception was the direct cause of the following exception:\n\n', 'Traceback (most recent call last):\n', '  File "C:\\Users\\giwrg\\OneDrive\\Υπολογιστής\\Licensy-0.9.14\\bot.py", line 111, in <module>\n    bot.load_extension(cog_path)\n', '  File "C:\\Users\\giwrg\\AppData\\Local\\Programs\\Python\\Python39\\lib\\site-packages\\discord\\ext\\commands\\bot.py", line 678, in load_extension\n    self._load_from_module_spec(spec, name)\n', '  File "C:\\Users\\giwrg\\AppData\\Local\\Programs\\Python\\Python39\\lib\\site-packages\\discord\\ext\\commands\\bot.py", line 609, in _load_from_module_spec\n    raise errors.ExtensionFailed(key, e) from e\n', "discord.ext.commands.errors.ExtensionFailed: Extension 'cogs.licenses' raised an error: ModuleNotFoundError: No module named 'dateutil'\n"] [root/<module>]
12-02-2022 17:19:49 - ERROR - ExtensionFailed: Extension 'cogs.bot_owner_commands' raised an error: ModuleNotFoundError: No module named 'dateutil' Failed to load extension cogs.bot_owner_commands [root/<module>]
12-02-2022 17:19:49 - WARNING - ['Traceback (most recent call last):\n', '  File "C:\\Users\\giwrg\\AppData\\Local\\Programs\\Python\\Python39\\lib\\site-packages\\discord\\ext\\commands\\bot.py", line 606, in _load_from_module_spec\n    spec.loader.exec_module(lib)\n', '  File "<frozen importlib._bootstrap_external>", line 850, in exec_module\n', '  File "<frozen importlib._bootstrap>", line 228, in _call_with_frames_removed\n', '  File "C:\\Users\\giwrg\\OneDrive\\Υπολογιστής\\Licensy-0.9.14\\cogs\\bot_owner_commands.py", line 8, in <module>\n    from helpers.converters import license_duration\n', '  File "C:\\Users\\giwrg\\OneDrive\\Υπολογιστής\\Licensy-0.9.14\\helpers\\converters.py", line 3, in <module>\n    from dateutil.relativedelta import relativedelta\n', "ModuleNotFoundError: No module named 'dateutil'\n", '\nThe above exception was the direct cause of the following exception:\n\n', 'Traceback (most recent call last):\n', '  File "C:\\Users\\giwrg\\OneDrive\\Υπολογιστής\\Licensy-0.9.14\\bot.py", line 111, in <module>\n    bot.load_extension(cog_path)\n', '  File "C:\\Users\\giwrg\\AppData\\Local\\Programs\\Python\\Python39\\lib\\site-packages\\discord\\ext\\commands\\bot.py", line 678, in load_extension\n    self._load_from_module_spec(spec, name)\n', '  File "C:\\Users\\giwrg\\AppData\\Local\\Programs\\Python\\Python39\\lib\\site-packages\\discord\\ext\\commands\\bot.py", line 609, in _load_from_module_spec\n    raise errors.ExtensionFailed(key, e) from e\n', "discord.ext.commands.errors.ExtensionFailed: Extension 'cogs.bot_owner_commands' raised an error: ModuleNotFoundError: No module named 'dateutil'\n"] [root/<module>]
12-02-2022 17:19:49 - ERROR - ExtensionFailed: Extension 'cogs.guild' raised an error: ModuleNotFoundError: No module named 'dateutil' Failed to load extension cogs.guild [root/<module>]
12-02-2022 17:19:49 - WARNING - ['Traceback (most recent call last):\n', '  File "C:\\Users\\giwrg\\AppData\\Local\\Programs\\Python\\Python39\\lib\\site-packages\\discord\\ext\\commands\\bot.py", line 606, in _load_from_module_spec\n    spec.loader.exec_module(lib)\n', '  File "<frozen importlib._bootstrap_external>", line 850, in exec_module\n', '  File "<frozen importlib._bootstrap>", line 228, in _call_with_frames_removed\n', '  File "C:\\Users\\giwrg\\OneDrive\\Υπολογιστής\\Licensy-0.9.14\\cogs\\guild.py", line 6, in <module>\n    from helpers.converters import license_duration\n', '  File "C:\\Users\\giwrg\\OneDrive\\Υπολογιστής\\Licensy-0.9.14\\helpers\\converters.py", line 3, in <module>\n    from dateutil.relativedelta import relativedelta\n', "ModuleNotFoundError: No module named 'dateutil'\n", '\nThe above exception was the direct cause of the following exception:\n\n', 'Traceback (most recent call last):\n', '  File "C:\\Users\\giwrg\\OneDrive\\Υπολογιστής\\Licensy-0.9.14\\bot.py", line 111, in <module>\n    bot.load_extension(cog_path)\n', '  File "C:\\Users\\giwrg\\AppData\\Local\\Programs\\Python\\Python39\\lib\\site-packages\\discord\\ext\\commands\\bot.py", line 678, in load_extension\n    self._load_from_module_spec(spec, name)\n', '  File "C:\\Users\\giwrg\\AppData\\Local\\Programs\\Python\\Python39\\lib\\site-packages\\discord\\ext\\commands\\bot.py", line 609, in _load_from_module_spec\n    raise errors.ExtensionFailed(key, e) from e\n', "discord.ext.commands.errors.ExtensionFailed: Extension 'cogs.guild' raised an error: ModuleNotFoundError: No module named 'dateutil'\n"] [root/<module>]
12-02-2022 17:19:49 - INFO - 	cogs.bot_information [root/<module>]
12-02-2022 17:19:49 - INFO - 	cogs.help [root/<module>]
12-02-2022 17:19:49 - ERROR - ExtensionFailed: Extension 'cogs.top_gg_api' raised an error: ModuleNotFoundError: No module named 'dbl' Failed to load extension cogs.top_gg_api [root/<module>]
12-02-2022 17:19:49 - WARNING - ['Traceback (most recent call last):\n', '  File "C:\\Users\\giwrg\\AppData\\Local\\Programs\\Python\\Python39\\lib\\site-packages\\discord\\ext\\commands\\bot.py", line 606, in _load_from_module_spec\n    spec.loader.exec_module(lib)\n', '  File "<frozen importlib._bootstrap_external>", line 850, in exec_module\n', '  File "<frozen importlib._bootstrap>", line 228, in _call_with_frames_removed\n', '  File "C:\\Users\\giwrg\\OneDrive\\Υπολογιστής\\Licensy-0.9.14\\cogs\\top_gg_api.py", line 2, in <module>\n    import dbl\n', "ModuleNotFoundError: No module named 'dbl'\n", '\nThe above exception was the direct cause of the following exception:\n\n', 'Traceback (most recent call last):\n', '  File "C:\\Users\\giwrg\\OneDrive\\Υπολογιστής\\Licensy-0.9.14\\bot.py", line 111, in <module>\n    bot.load_extension(cog_path)\n', '  File "C:\\Users\\giwrg\\AppData\\Local\\Programs\\Python\\Python39\\lib\\site-packages\\discord\\ext\\commands\\bot.py", line 678, in load_extension\n    self._load_from_module_spec(spec, name)\n', '  File "C:\\Users\\giwrg\\AppData\\Local\\Programs\\Python\\Python39\\lib\\site-packages\\discord\\ext\\commands\\bot.py", line 609, in _load_from_module_spec\n    raise errors.ExtensionFailed(key, e) from e\n', "discord.ext.commands.errors.ExtensionFailed: Extension 'cogs.top_gg_api' raised an error: ModuleNotFoundError: No module named 'dbl'\n"] [root/<module>]
12-02-2022 17:19:49 - INFO - 	cogs.cmd_errors [root/<module>]
12-02-2022 17:19:49 - INFO - Starting activity loop.. [cogs.bot_information/before_activity_loop]
12-02-2022 17:19:50 - INFO - Connection to Discord established [root/on_connect]
12-02-2022 17:19:52 - INFO - Activity loop started! [cogs.bot_information/before_activity_loop]
12-02-2022 17:19:52 - INFO - Logged in as: FiveM $nban Helper - 823233083305623572	DiscordPy version: 1.7.3 [root/on_ready]
12-02-2022 17:19:52 - INFO - Successfully logged in and booted...! [root/on_ready]
12-02-2022 17:20:37 - INFO - Connection to database established. [database_handler/create_instance]
12-02-2022 17:20:37 - WARNING - PyNaCl is not installed, voice will NOT be supported [discord.client/__init__]
12-02-2022 17:20:37 - INFO - Loaded extensions: [root/<module>]
12-02-2022 17:20:37 - ERROR - ExtensionFailed: Extension 'cogs.licenses' raised an error: ModuleNotFoundError: No module named 'dateutil' Failed to load extension cogs.licenses [root/<module>]
12-02-2022 17:20:37 - WARNING - ['Traceback (most recent call last):\n', '  File "C:\\Users\\giwrg\\AppData\\Local\\Programs\\Python\\Python39\\lib\\site-packages\\discord\\ext\\commands\\bot.py", line 606, in _load_from_module_spec\n    spec.loader.exec_module(lib)\n', '  File "<frozen importlib._bootstrap_external>", line 850, in exec_module\n', '  File "<frozen importlib._bootstrap>", line 228, in _call_with_frames_removed\n', '  File "C:\\Users\\giwrg\\OneDrive\\Υπολογιστής\\Licensy-0.9.14\\cogs\\licenses.py", line 3, in <module>\n    from dateutil import parser\n', "ModuleNotFoundError: No module named 'dateutil'\n", '\nThe above exception was the direct cause of the following exception:\n\n', 'Traceback (most recent call last):\n', '  File "C:\\Users\\giwrg\\OneDrive\\Υπολογιστής\\Licensy-0.9.14\\bot.py", line 111, in <module>\n    bot.load_extension(cog_path)\n', '  File "C:\\Users\\giwrg\\AppData\\Local\\Programs\\Python\\Python39\\lib\\site-packages\\discord\\ext\\commands\\bot.py", line 678, in load_extension\n    self._load_from_module_spec(spec, name)\n', '  File "C:\\Users\\giwrg\\AppData\\Local\\Programs\\Python\\Python39\\lib\\site-packages\\discord\\ext\\commands\\bot.py", line 609, in _load_from_module_spec\n    raise errors.ExtensionFailed(key, e) from e\n', "discord.ext.commands.errors.ExtensionFailed: Extension 'cogs.licenses' raised an error: ModuleNotFoundError: No module named 'dateutil'\n"] [root/<module>]
12-02-2022 17:20:37 - ERROR - ExtensionFailed: Extension 'cogs.bot_owner_commands' raised an error: ModuleNotFoundError: No module named 'dateutil' Failed to load extension cogs.bot_owner_commands [root/<module>]
12-02-2022 17:20:37 - WARNING - ['Traceback (most recent call last):\n', '  File "C:\\Users\\giwrg\\AppData\\Local\\Programs\\Python\\Python39\\lib\\site-packages\\discord\\ext\\commands\\bot.py", line 606, in _load_from_module_spec\n    spec.loader.exec_module(lib)\n', '  File "<frozen importlib._bootstrap_external>", line 850, in exec_module\n', '  File "<frozen importlib._bootstrap>", line 228, in _call_with_frames_removed\n', '  File "C:\\Users\\giwrg\\OneDrive\\Υπολογιστής\\Licensy-0.9.14\\cogs\\bot_owner_commands.py", line 8, in <module>\n    from helpers.converters import license_duration\n', '  File "C:\\Users\\giwrg\\OneDrive\\Υπολογιστής\\Licensy-0.9.14\\helpers\\converters.py", line 3, in <module>\n    from dateutil.relativedelta import relativedelta\n', "ModuleNotFoundError: No module named 'dateutil'\n", '\nThe above exception was the direct cause of the following exception:\n\n', 'Traceback (most recent call last):\n', '  File "C:\\Users\\giwrg\\OneDrive\\Υπολογιστής\\Licensy-0.9.14\\bot.py", line 111, in <module>\n    bot.load_extension(cog_path)\n', '  File "C:\\Users\\giwrg\\AppData\\Local\\Programs\\Python\\Python39\\lib\\site-packages\\discord\\ext\\commands\\bot.py", line 678, in load_extension\n    self._load_from_module_spec(spec, name)\n', '  File "C:\\Users\\giwrg\\AppData\\Local\\Programs\\Python\\Python39\\lib\\site-packages\\discord\\ext\\commands\\bot.py", line 609, in _load_from_module_spec\n    raise errors.ExtensionFailed(key, e) from e\n', "discord.ext.commands.errors.ExtensionFailed: Extension 'cogs.bot_owner_commands' raised an error: ModuleNotFoundError: No module named 'dateutil'\n"] [root/<module>]
12-02-2022 17:20:37 - ERROR - ExtensionFailed: Extension 'cogs.guild' raised an error: ModuleNotFoundError: No module named 'dateutil' Failed to load extension cogs.guild [root/<module>]
12-02-2022 17:20:37 - WARNING - ['Traceback (most recent call last):\n', '  File "C:\\Users\\giwrg\\AppData\\Local\\Programs\\Python\\Python39\\lib\\site-packages\\discord\\ext\\commands\\bot.py", line 606, in _load_from_module_spec\n    spec.loader.exec_module(lib)\n', '  File "<frozen importlib._bootstrap_external>", line 850, in exec_module\n', '  File "<frozen importlib._bootstrap>", line 228, in _call_with_frames_removed\n', '  File "C:\\Users\\giwrg\\OneDrive\\Υπολογιστής\\Licensy-0.9.14\\cogs\\guild.py", line 6, in <module>\n    from helpers.converters import license_duration\n', '  File "C:\\Users\\giwrg\\OneDrive\\Υπολογιστής\\Licensy-0.9.14\\helpers\\converters.py", line 3, in <module>\n    from dateutil.relativedelta import relativedelta\n', "ModuleNotFoundError: No module named 'dateutil'\n", '\nThe above exception was the direct cause of the following exception:\n\n', 'Traceback (most recent call last):\n', '  File "C:\\Users\\giwrg\\OneDrive\\Υπολογιστής\\Licensy-0.9.14\\bot.py", line 111, in <module>\n    bot.load_extension(cog_path)\n', '  File "C:\\Users\\giwrg\\AppData\\Local\\Programs\\Python\\Python39\\lib\\site-packages\\discord\\ext\\commands\\bot.py", line 678, in load_extension\n    self._load_from_module_spec(spec, name)\n', '  File "C:\\Users\\giwrg\\AppData\\Local\\Programs\\Python\\Python39\\lib\\site-packages\\discord\\ext\\commands\\bot.py", line 609, in _load_from_module_spec\n    raise errors.ExtensionFailed(key, e) from e\n', "discord.ext.commands.errors.ExtensionFailed: Extension 'cogs.guild' raised an error: ModuleNotFoundError: No module named 'dateutil'\n"] [root/<module>]
12-02-2022 17:20:37 - INFO - 	cogs.bot_information [root/<module>]
12-02-2022 17:20:37 - INFO - 	cogs.help [root/<module>]
12-02-2022 17:20:37 - ERROR - ExtensionFailed: Extension 'cogs.top_gg_api' raised an error: ModuleNotFoundError: No module named 'dbl' Failed to load extension cogs.top_gg_api [root/<module>]
12-02-2022 17:20:37 - WARNING - ['Traceback (most recent call last):\n', '  File "C:\\Users\\giwrg\\AppData\\Local\\Programs\\Python\\Python39\\lib\\site-packages\\discord\\ext\\commands\\bot.py", line 606, in _load_from_module_spec\n    spec.loader.exec_module(lib)\n', '  File "<frozen importlib._bootstrap_external>", line 850, in exec_module\n', '  File "<frozen importlib._bootstrap>", line 228, in _call_with_frames_removed\n', '  File "C:\\Users\\giwrg\\OneDrive\\Υπολογιστής\\Licensy-0.9.14\\cogs\\top_gg_api.py", line 2, in <module>\n    import dbl\n', "ModuleNotFoundError: No module named 'dbl'\n", '\nThe above exception was the direct cause of the following exception:\n\n', 'Traceback (most recent call last):\n', '  File "C:\\Users\\giwrg\\OneDrive\\Υπολογιστής\\Licensy-0.9.14\\bot.py", line 111, in <module>\n    bot.load_extension(cog_path)\n', '  File "C:\\Users\\giwrg\\AppData\\Local\\Programs\\Python\\Python39\\lib\\site-packages\\discord\\ext\\commands\\bot.py", line 678, in load_extension\n    self._load_from_module_spec(spec, name)\n', '  File "C:\\Users\\giwrg\\AppData\\Local\\Programs\\Python\\Python39\\lib\\site-packages\\discord\\ext\\commands\\bot.py", line 609, in _load_from_module_spec\n    raise errors.ExtensionFailed(key, e) from e\n', "discord.ext.commands.errors.ExtensionFailed: Extension 'cogs.top_gg_api' raised an error: ModuleNotFoundError: No module named 'dbl'\n"] [root/<module>]
12-02-2022 17:20:37 - INFO - 	cogs.cmd_errors [root/<module>]
12-02-2022 17:20:37 - INFO - Starting activity loop.. [cogs.bot_information/before_activity_loop]
12-02-2022 17:20:38 - INFO - Connection to Discord established [root/on_connect]
12-02-2022 17:20:40 - INFO - Activity loop started! [cogs.bot_information/before_activity_loop]
12-02-2022 17:20:40 - INFO - Logged in as: FiveM $nban Helper - 823233083305623572	DiscordPy version: 1.7.3 [root/on_ready]
12-02-2022 17:20:40 - INFO - Successfully logged in and booted...! [root/on_ready]
12-02-2022 17:21:28 - INFO - Connection to database established. [database_handler/create_instance]
12-02-2022 17:21:28 - WARNING - PyNaCl is not installed, voice will NOT be supported [discord.client/__init__]
12-02-2022 17:21:28 - INFO - Loaded extensions: [root/<module>]
12-02-2022 17:21:28 - ERROR - ExtensionFailed: Extension 'cogs.licenses' raised an error: ModuleNotFoundError: No module named 'dateutil' Failed to load extension cogs.licenses [root/<module>]
12-02-2022 17:21:28 - WARNING - ['Traceback (most recent call last):\n', '  File "C:\\Users\\giwrg\\AppData\\Local\\Programs\\Python\\Python39\\lib\\site-packages\\discord\\ext\\commands\\bot.py", line 606, in _load_from_module_spec\n    spec.loader.exec_module(lib)\n', '  File "<frozen importlib._bootstrap_external>", line 850, in exec_module\n', '  File "<frozen importlib._bootstrap>", line 228, in _call_with_frames_removed\n', '  File "C:\\Users\\giwrg\\OneDrive\\Υπολογιστής\\Licensy-0.9.14\\cogs\\licenses.py", line 3, in <module>\n    from dateutil import parser\n', "ModuleNotFoundError: No module named 'dateutil'\n", '\nThe above exception was the direct cause of the following exception:\n\n', 'Traceback (most recent call last):\n', '  File "C:\\Users\\giwrg\\OneDrive\\Υπολογιστής\\Licensy-0.9.14\\bot.py", line 111, in <module>\n    bot.load_extension(cog_path)\n', '  File "C:\\Users\\giwrg\\AppData\\Local\\Programs\\Python\\Python39\\lib\\site-packages\\discord\\ext\\commands\\bot.py", line 678, in load_extension\n    self._load_from_module_spec(spec, name)\n', '  File "C:\\Users\\giwrg\\AppData\\Local\\Programs\\Python\\Python39\\lib\\site-packages\\discord\\ext\\commands\\bot.py", line 609, in _load_from_module_spec\n    raise errors.ExtensionFailed(key, e) from e\n', "discord.ext.commands.errors.ExtensionFailed: Extension 'cogs.licenses' raised an error: ModuleNotFoundError: No module named 'dateutil'\n"] [root/<module>]
12-02-2022 17:21:28 - ERROR - ExtensionFailed: Extension 'cogs.bot_owner_commands' raised an error: ModuleNotFoundError: No module named 'dateutil' Failed to load extension cogs.bot_owner_commands [root/<module>]
12-02-2022 17:21:28 - WARNING - ['Traceback (most recent call last):\n', '  File "C:\\Users\\giwrg\\AppData\\Local\\Programs\\Python\\Python39\\lib\\site-packages\\discord\\ext\\commands\\bot.py", line 606, in _load_from_module_spec\n    spec.loader.exec_module(lib)\n', '  File "<frozen importlib._bootstrap_external>", line 850, in exec_module\n', '  File "<frozen importlib._bootstrap>", line 228, in _call_with_frames_removed\n', '  File "C:\\Users\\giwrg\\OneDrive\\Υπολογιστής\\Licensy-0.9.14\\cogs\\bot_owner_commands.py", line 8, in <module>\n    from helpers.converters import license_duration\n', '  File "C:\\Users\\giwrg\\OneDrive\\Υπολογιστής\\Licensy-0.9.14\\helpers\\converters.py", line 3, in <module>\n    from dateutil.relativedelta import relativedelta\n', "ModuleNotFoundError: No module named 'dateutil'\n", '\nThe above exception was the direct cause of the following exception:\n\n', 'Traceback (most recent call last):\n', '  File "C:\\Users\\giwrg\\OneDrive\\Υπολογιστής\\Licensy-0.9.14\\bot.py", line 111, in <module>\n    bot.load_extension(cog_path)\n', '  File "C:\\Users\\giwrg\\AppData\\Local\\Programs\\Python\\Python39\\lib\\site-packages\\discord\\ext\\commands\\bot.py", line 678, in load_extension\n    self._load_from_module_spec(spec, name)\n', '  File "C:\\Users\\giwrg\\AppData\\Local\\Programs\\Python\\Python39\\lib\\site-packages\\discord\\ext\\commands\\bot.py", line 609, in _load_from_module_spec\n    raise errors.ExtensionFailed(key, e) from e\n', "discord.ext.commands.errors.ExtensionFailed: Extension 'cogs.bot_owner_commands' raised an error: ModuleNotFoundError: No module named 'dateutil'\n"] [root/<module>]
12-02-2022 17:21:28 - ERROR - ExtensionFailed: Extension 'cogs.guild' raised an error: ModuleNotFoundError: No module named 'dateutil' Failed to load extension cogs.guild [root/<module>]
12-02-2022 17:21:28 - WARNING - ['Traceback (most recent call last):\n', '  File "C:\\Users\\giwrg\\AppData\\Local\\Programs\\Python\\Python39\\lib\\site-packages\\discord\\ext\\commands\\bot.py", line 606, in _load_from_module_spec\n    spec.loader.exec_module(lib)\n', '  File "<frozen importlib._bootstrap_external>", line 850, in exec_module\n', '  File "<frozen importlib._bootstrap>", line 228, in _call_with_frames_removed\n', '  File "C:\\Users\\giwrg\\OneDrive\\Υπολογιστής\\Licensy-0.9.14\\cogs\\guild.py", line 6, in <module>\n    from helpers.converters import license_duration\n', '  File "C:\\Users\\giwrg\\OneDrive\\Υπολογιστής\\Licensy-0.9.14\\helpers\\converters.py", line 3, in <module>\n    from dateutil.relativedelta import relativedelta\n', "ModuleNotFoundError: No module named 'dateutil'\n", '\nThe above exception was the direct cause of the following exception:\n\n', 'Traceback (most recent call last):\n', '  File "C:\\Users\\giwrg\\OneDrive\\Υπολογιστής\\Licensy-0.9.14\\bot.py", line 111, in <module>\n    bot.load_extension(cog_path)\n', '  File "C:\\Users\\giwrg\\AppData\\Local\\Programs\\Python\\Python39\\lib\\site-packages\\discord\\ext\\commands\\bot.py", line 678, in load_extension\n    self._load_from_module_spec(spec, name)\n', '  File "C:\\Users\\giwrg\\AppData\\Local\\Programs\\Python\\Python39\\lib\\site-packages\\discord\\ext\\commands\\bot.py", line 609, in _load_from_module_spec\n    raise errors.ExtensionFailed(key, e) from e\n', "discord.ext.commands.errors.ExtensionFailed: Extension 'cogs.guild' raised an error: ModuleNotFoundError: No module named 'dateutil'\n"] [root/<module>]
12-02-2022 17:21:28 - INFO - 	cogs.bot_information [root/<module>]
12-02-2022 17:21:28 - INFO - 	cogs.help [root/<module>]
12-02-2022 17:21:28 - INFO - 	cogs.top_gg_api [root/<module>]
12-02-2022 17:21:28 - INFO - 	cogs.cmd_errors [root/<module>]
12-02-2022 17:21:28 - INFO - Starting activity loop.. [cogs.bot_information/before_activity_loop]
12-02-2022 17:21:28 - INFO - Starting update stats loop loop.. [cogs.top_gg_api/before_update_stats_loop]
12-02-2022 17:21:28 - INFO - Connection to Discord established [root/on_connect]
12-02-2022 17:21:31 - INFO - Activity loop started! [cogs.bot_information/before_activity_loop]
12-02-2022 17:21:31 - INFO - Update stats loop started! [cogs.top_gg_api/before_update_stats_loop]
12-02-2022 17:21:31 - INFO - Logged in as: FiveM $nban Helper - 823233083305623572	DiscordPy version: 1.7.3 [root/on_ready]
12-02-2022 17:21:31 - INFO - Successfully logged in and booted...! [root/on_ready]
12-02-2022 17:21:31 - ERROR - Failed to post server count
TypeError: object Lock can't be used in 'await' expression [cogs.top_gg_api/update_stats_loop]
Traceback (most recent call last):
  File "C:\Users\giwrg\OneDrive\Υπολογιστής\Licensy-0.9.14\cogs\top_gg_api.py", line 20, in update_stats_loop
    await self.dbl_client.post_guild_count()
  File "C:\Users\giwrg\AppData\Local\Programs\Python\Python39\lib\site-packages\dbl\client.py", line 160, in post_guild_count
    await self.http.post_guild_count(guild_count, shard_count, shard_id)
  File "C:\Users\giwrg\AppData\Local\Programs\Python\Python39\lib\site-packages\dbl\http.py", line 168, in post_guild_count
    await self.request('POST', '/bots/stats', json=payload)
  File "C:\Users\giwrg\AppData\Local\Programs\Python\Python39\lib\site-packages\dbl\http.py", line 93, in request
    async with rate_limiter:  # this works but doesn't 'save' over restart.
  File "<string>", line 6, in __aenter__
TypeError: object Lock can't be used in 'await' expression
12-02-2022 17:21:46 - ERROR - Can't get guild Luxury Shop prefix. Error:'NoneType' object is not subscriptable. Using '!' as prefix. [root/prefix_callable]
12-02-2022 17:22:04 - INFO - Connection to database established. [database_handler/create_instance]
12-02-2022 17:22:04 - WARNING - PyNaCl is not installed, voice will NOT be supported [discord.client/__init__]
12-02-2022 17:22:04 - INFO - Loaded extensions: [root/<module>]
12-02-2022 17:22:04 - ERROR - ExtensionFailed: Extension 'cogs.licenses' raised an error: ModuleNotFoundError: No module named 'texttable' Failed to load extension cogs.licenses [root/<module>]
12-02-2022 17:22:04 - WARNING - ['Traceback (most recent call last):\n', '  File "C:\\Users\\giwrg\\AppData\\Local\\Programs\\Python\\Python39\\lib\\site-packages\\discord\\ext\\commands\\bot.py", line 606, in _load_from_module_spec\n    spec.loader.exec_module(lib)\n', '  File "<frozen importlib._bootstrap_external>", line 850, in exec_module\n', '  File "<frozen importlib._bootstrap>", line 228, in _call_with_frames_removed\n', '  File "C:\\Users\\giwrg\\OneDrive\\Υπολογιστής\\Licensy-0.9.14\\cogs\\licenses.py", line 4, in <module>\n    import texttable\n', "ModuleNotFoundError: No module named 'texttable'\n", '\nThe above exception was the direct cause of the following exception:\n\n', 'Traceback (most recent call last):\n', '  File "C:\\Users\\giwrg\\OneDrive\\Υπολογιστής\\Licensy-0.9.14\\bot.py", line 111, in <module>\n    bot.load_extension(cog_path)\n', '  File "C:\\Users\\giwrg\\AppData\\Local\\Programs\\Python\\Python39\\lib\\site-packages\\discord\\ext\\commands\\bot.py", line 678, in load_extension\n    self._load_from_module_spec(spec, name)\n', '  File "C:\\Users\\giwrg\\AppData\\Local\\Programs\\Python\\Python39\\lib\\site-packages\\discord\\ext\\commands\\bot.py", line 609, in _load_from_module_spec\n    raise errors.ExtensionFailed(key, e) from e\n', "discord.ext.commands.errors.ExtensionFailed: Extension 'cogs.licenses' raised an error: ModuleNotFoundError: No module named 'texttable'\n"] [root/<module>]
12-02-2022 17:22:04 - INFO - 	cogs.bot_owner_commands [root/<module>]
12-02-2022 17:22:04 - INFO - 	cogs.guild [root/<module>]
12-02-2022 17:22:04 - INFO - 	cogs.bot_information [root/<module>]
12-02-2022 17:22:04 - INFO - 	cogs.help [root/<module>]
12-02-2022 17:22:04 - INFO - 	cogs.top_gg_api [root/<module>]
12-02-2022 17:22:04 - INFO - 	cogs.cmd_errors [root/<module>]
12-02-2022 17:22:04 - INFO - Starting activity loop.. [cogs.bot_information/before_activity_loop]
12-02-2022 17:22:04 - INFO - Starting update stats loop loop.. [cogs.top_gg_api/before_update_stats_loop]
12-02-2022 17:22:04 - INFO - Starting database guild checkup.. [cogs.guild/startup_guild_database_check]
12-02-2022 17:22:05 - INFO - Connection to Discord established [root/on_connect]
12-02-2022 17:22:07 - INFO - Activity loop started! [cogs.bot_information/before_activity_loop]
12-02-2022 17:22:07 - INFO - Update stats loop started! [cogs.top_gg_api/before_update_stats_loop]
12-02-2022 17:22:07 - INFO - Guild 744176622067777542 Luxury Shop found but not registered. Adding entry to database. [cogs.guild/startup_guild_database_check]
12-02-2022 17:22:07 - INFO - Logged in as: FiveM $nban Helper - 823233083305623572	DiscordPy version: 1.7.3 [root/on_ready]
12-02-2022 17:22:07 - INFO - Successfully logged in and booted...! [root/on_ready]
12-02-2022 17:22:07 - ERROR - Failed to post server count
TypeError: object Lock can't be used in 'await' expression [cogs.top_gg_api/update_stats_loop]
Traceback (most recent call last):
  File "C:\Users\giwrg\OneDrive\Υπολογιστής\Licensy-0.9.14\cogs\top_gg_api.py", line 20, in update_stats_loop
    await self.dbl_client.post_guild_count()
  File "C:\Users\giwrg\AppData\Local\Programs\Python\Python39\lib\site-packages\dbl\client.py", line 160, in post_guild_count
    await self.http.post_guild_count(guild_count, shard_count, shard_id)
  File "C:\Users\giwrg\AppData\Local\Programs\Python\Python39\lib\site-packages\dbl\http.py", line 168, in post_guild_count
    await self.request('POST', '/bots/stats', json=payload)
  File "C:\Users\giwrg\AppData\Local\Programs\Python\Python39\lib\site-packages\dbl\http.py", line 93, in request
    async with rate_limiter:  # this works but doesn't 'save' over restart.
  File "<string>", line 6, in __aenter__
TypeError: object Lock can't be used in 'await' expression
12-02-2022 17:22:07 - INFO - Database guild checkup done! [cogs.guild/startup_guild_database_check]
12-02-2022 17:23:16 - INFO - Connection to database established. [database_handler/create_instance]
12-02-2022 17:23:16 - WARNING - PyNaCl is not installed, voice will NOT be supported [discord.client/__init__]
12-02-2022 17:23:16 - INFO - Loaded extensions: [root/<module>]
12-02-2022 17:23:16 - INFO - 	cogs.licenses [root/<module>]
12-02-2022 17:23:16 - INFO - 	cogs.bot_owner_commands [root/<module>]
12-02-2022 17:23:16 - INFO - 	cogs.guild [root/<module>]
12-02-2022 17:23:16 - INFO - 	cogs.bot_information [root/<module>]
12-02-2022 17:23:16 - INFO - 	cogs.help [root/<module>]
12-02-2022 17:23:16 - INFO - 	cogs.top_gg_api [root/<module>]
12-02-2022 17:23:16 - INFO - 	cogs.cmd_errors [root/<module>]
12-02-2022 17:23:16 - INFO - Starting license check loop.. [cogs.licenses/before_printer]
12-02-2022 17:23:16 - INFO - Starting activity loop.. [cogs.bot_information/before_activity_loop]
12-02-2022 17:23:16 - INFO - Starting update stats loop loop.. [cogs.top_gg_api/before_update_stats_loop]
12-02-2022 17:23:16 - INFO - Starting database guild checkup.. [cogs.guild/startup_guild_database_check]
12-02-2022 17:23:17 - INFO - Connection to Discord established [root/on_connect]
12-02-2022 17:23:19 - INFO - License check loop started! [cogs.licenses/before_printer]
12-02-2022 17:23:19 - INFO - Activity loop started! [cogs.bot_information/before_activity_loop]
12-02-2022 17:23:19 - INFO - Update stats loop started! [cogs.top_gg_api/before_update_stats_loop]
12-02-2022 17:23:19 - INFO - Database guild checkup done! [cogs.guild/startup_guild_database_check]
12-02-2022 17:23:19 - INFO - Logged in as: FiveM $nban Helper - 823233083305623572	DiscordPy version: 1.7.3 [root/on_ready]
12-02-2022 17:23:19 - INFO - Successfully logged in and booted...! [root/on_ready]
12-02-2022 17:23:19 - ERROR - Failed to post server count
TypeError: object Lock can't be used in 'await' expression [cogs.top_gg_api/update_stats_loop]
Traceback (most recent call last):
  File "C:\Users\giwrg\OneDrive\Υπολογιστής\Licensy-0.9.14\cogs\top_gg_api.py", line 20, in update_stats_loop
    await self.dbl_client.post_guild_count()
  File "C:\Users\giwrg\AppData\Local\Programs\Python\Python39\lib\site-packages\dbl\client.py", line 160, in post_guild_count
    await self.http.post_guild_count(guild_count, shard_count, shard_id)
  File "C:\Users\giwrg\AppData\Local\Programs\Python\Python39\lib\site-packages\dbl\http.py", line 168, in post_guild_count
    await self.request('POST', '/bots/stats', json=payload)
  File "C:\Users\giwrg\AppData\Local\Programs\Python\Python39\lib\site-packages\dbl\http.py", line 93, in request
    async with rate_limiter:  # this works but doesn't 'save' over restart.
  File "<string>", line 6, in __aenter__
TypeError: object Lock can't be used in 'await' expression
12-02-2022 17:26:24 - INFO - Connection to database established. [database_handler/create_instance]
12-02-2022 17:26:24 - WARNING - PyNaCl is not installed, voice will NOT be supported [discord.client/__init__]
12-02-2022 17:26:24 - INFO - Loaded extensions: [root/<module>]
12-02-2022 17:26:24 - INFO - 	cogs.licenses [root/<module>]
12-02-2022 17:26:24 - INFO - 	cogs.bot_owner_commands [root/<module>]
12-02-2022 17:26:24 - INFO - 	cogs.guild [root/<module>]
12-02-2022 17:26:24 - INFO - 	cogs.bot_information [root/<module>]
12-02-2022 17:26:24 - INFO - 	cogs.help [root/<module>]
12-02-2022 17:26:24 - INFO - 	cogs.top_gg_api [root/<module>]
12-02-2022 17:26:24 - INFO - 	cogs.cmd_errors [root/<module>]
12-02-2022 17:26:24 - INFO - Starting license check loop.. [cogs.licenses/before_printer]
12-02-2022 17:26:24 - INFO - Starting activity loop.. [cogs.bot_information/before_activity_loop]
12-02-2022 17:26:24 - INFO - Starting update stats loop loop.. [cogs.top_gg_api/before_update_stats_loop]
12-02-2022 17:26:24 - INFO - Starting database guild checkup.. [cogs.guild/startup_guild_database_check]
12-02-2022 17:26:25 - INFO - Connection to Discord established [root/on_connect]
12-02-2022 17:26:27 - INFO - License check loop started! [cogs.licenses/before_printer]
12-02-2022 17:26:27 - INFO - Activity loop started! [cogs.bot_information/before_activity_loop]
12-02-2022 17:26:27 - INFO - Update stats loop started! [cogs.top_gg_api/before_update_stats_loop]
12-02-2022 17:26:27 - INFO - Database guild checkup done! [cogs.guild/startup_guild_database_check]
12-02-2022 17:26:27 - INFO - Logged in as: FiveM $nban Helper - 823233083305623572	DiscordPy version: 1.7.3 [root/on_ready]
12-02-2022 17:26:27 - INFO - Successfully logged in and booted...! [root/on_ready]
12-02-2022 17:26:27 - ERROR - Failed to post server count
TypeError: object Lock can't be used in 'await' expression [cogs.top_gg_api/update_stats_loop]
Traceback (most recent call last):
  File "C:\Users\giwrg\OneDrive\Υπολογιστής\Licensy-0.9.14\cogs\top_gg_api.py", line 20, in update_stats_loop
    await self.dbl_client.post_guild_count()
  File "C:\Users\giwrg\AppData\Local\Programs\Python\Python39\lib\site-packages\dbl\client.py", line 160, in post_guild_count
    await self.http.post_guild_count(guild_count, shard_count, shard_id)
  File "C:\Users\giwrg\AppData\Local\Programs\Python\Python39\lib\site-packages\dbl\http.py", line 168, in post_guild_count
    await self.request('POST', '/bots/stats', json=payload)
  File "C:\Users\giwrg\AppData\Local\Programs\Python\Python39\lib\site-packages\dbl\http.py", line 93, in request
    async with rate_limiter:  # this works but doesn't 'save' over restart.
  File "<string>", line 6, in __aenter__
TypeError: object Lock can't be used in 'await' expression
12-02-2022 17:29:41 - INFO - Connection to database established. [database_handler/create_instance]
12-02-2022 17:29:41 - WARNING - PyNaCl is not installed, voice will NOT be supported [discord.client/__init__]
12-02-2022 17:29:41 - INFO - Loaded extensions: [root/<module>]
12-02-2022 17:29:41 - INFO - 	cogs.licenses [root/<module>]
12-02-2022 17:29:41 - INFO - 	cogs.bot_owner_commands [root/<module>]
12-02-2022 17:29:41 - INFO - 	cogs.guild [root/<module>]
12-02-2022 17:29:41 - INFO - 	cogs.bot_information [root/<module>]
12-02-2022 17:29:41 - INFO - 	cogs.help [root/<module>]
12-02-2022 17:29:41 - INFO - 	cogs.top_gg_api [root/<module>]
12-02-2022 17:29:41 - INFO - 	cogs.cmd_errors [root/<module>]
12-02-2022 17:29:41 - INFO - Starting license check loop.. [cogs.licenses/before_printer]
12-02-2022 17:29:41 - INFO - Starting activity loop.. [cogs.bot_information/before_activity_loop]
12-02-2022 17:29:41 - INFO - Starting update stats loop loop.. [cogs.top_gg_api/before_update_stats_loop]
12-02-2022 17:29:41 - INFO - Starting database guild checkup.. [cogs.guild/startup_guild_database_check]
12-02-2022 17:29:42 - INFO - Connection to Discord established [root/on_connect]
12-02-2022 17:29:44 - INFO - License check loop started! [cogs.licenses/before_printer]
12-02-2022 17:29:44 - INFO - Activity loop started! [cogs.bot_information/before_activity_loop]
12-02-2022 17:29:44 - INFO - Update stats loop started! [cogs.top_gg_api/before_update_stats_loop]
12-02-2022 17:29:44 - INFO - Database guild checkup done! [cogs.guild/startup_guild_database_check]
12-02-2022 17:29:44 - INFO - Logged in as: FiveM $nban Helper - 823233083305623572	DiscordPy version: 1.7.3 [root/on_ready]
12-02-2022 17:29:44 - INFO - Successfully logged in and booted...! [root/on_ready]
12-02-2022 17:29:44 - ERROR - Failed to post server count
TypeError: object Lock can't be used in 'await' expression [cogs.top_gg_api/update_stats_loop]
Traceback (most recent call last):
  File "C:\Users\giwrg\OneDrive\Υπολογιστής\Licensy-0.9.14\cogs\top_gg_api.py", line 20, in update_stats_loop
    await self.dbl_client.post_guild_count()
  File "C:\Users\giwrg\AppData\Local\Programs\Python\Python39\lib\site-packages\dbl\client.py", line 160, in post_guild_count
    await self.http.post_guild_count(guild_count, shard_count, shard_id)
  File "C:\Users\giwrg\AppData\Local\Programs\Python\Python39\lib\site-packages\dbl\http.py", line 168, in post_guild_count
    await self.request('POST', '/bots/stats', json=payload)
  File "C:\Users\giwrg\AppData\Local\Programs\Python\Python39\lib\site-packages\dbl\http.py", line 93, in request
    async with rate_limiter:  # this works but doesn't 'save' over restart.
  File "<string>", line 6, in __aenter__
TypeError: object Lock can't be used in 'await' expression
12-02-2022 18:46:32 - INFO - Connection to database established. [database_handler/create_instance]
12-02-2022 18:46:32 - WARNING - PyNaCl is not installed, voice will NOT be supported [discord.client/__init__]
12-02-2022 18:46:32 - INFO - Loaded extensions: [root/<module>]
12-02-2022 18:46:32 - INFO - 	cogs.licenses [root/<module>]
12-02-2022 18:46:32 - INFO - 	cogs.bot_owner_commands [root/<module>]
12-02-2022 18:46:32 - INFO - 	cogs.guild [root/<module>]
12-02-2022 18:46:32 - INFO - 	cogs.bot_information [root/<module>]
12-02-2022 18:46:32 - INFO - 	cogs.help [root/<module>]
12-02-2022 18:46:33 - INFO - 	cogs.top_gg_api [root/<module>]
12-02-2022 18:46:33 - INFO - 	cogs.cmd_errors [root/<module>]
12-02-2022 18:46:33 - INFO - Starting license check loop.. [cogs.licenses/before_printer]
12-02-2022 18:46:33 - INFO - Starting activity loop.. [cogs.bot_information/before_activity_loop]
12-02-2022 18:46:33 - INFO - Starting update stats loop loop.. [cogs.top_gg_api/before_update_stats_loop]
12-02-2022 18:46:33 - INFO - Starting database guild checkup.. [cogs.guild/startup_guild_database_check]
12-02-2022 18:46:33 - INFO - Connection to Discord established [root/on_connect]
12-02-2022 18:46:35 - INFO - License check loop started! [cogs.licenses/before_printer]
12-02-2022 18:46:35 - INFO - Activity loop started! [cogs.bot_information/before_activity_loop]
12-02-2022 18:46:35 - INFO - Update stats loop started! [cogs.top_gg_api/before_update_stats_loop]
12-02-2022 18:46:35 - INFO - Database guild checkup done! [cogs.guild/startup_guild_database_check]
12-02-2022 18:46:35 - INFO - Logged in as: FiveM $nban Helper - 823233083305623572	DiscordPy version: 1.7.3 [root/on_ready]
12-02-2022 18:46:35 - INFO - Successfully logged in and booted...! [root/on_ready]
12-02-2022 18:46:35 - ERROR - Failed to post server count
TypeError: object Lock can't be used in 'await' expression [cogs.top_gg_api/update_stats_loop]
Traceback (most recent call last):
  File "C:\Users\giwrg\OneDrive\Υπολογιστής\Licensy-0.9.14\cogs\top_gg_api.py", line 20, in update_stats_loop
    await self.dbl_client.post_guild_count()
  File "C:\Users\giwrg\AppData\Local\Programs\Python\Python39\lib\site-packages\dbl\client.py", line 160, in post_guild_count
    await self.http.post_guild_count(guild_count, shard_count, shard_id)
  File "C:\Users\giwrg\AppData\Local\Programs\Python\Python39\lib\site-packages\dbl\http.py", line 168, in post_guild_count
    await self.request('POST', '/bots/stats', json=payload)
  File "C:\Users\giwrg\AppData\Local\Programs\Python\Python39\lib\site-packages\dbl\http.py", line 93, in request
    async with rate_limiter:  # this works but doesn't 'save' over restart.
  File "<string>", line 6, in __aenter__
TypeError: object Lock can't be used in 'await' expression
